Traceback (most recent call last):
  File "/var/www/ElderMedManagement/zenboPack/zenboAwake.py", line 9, in <module>
    zenbo = pyzenbo.connect(host)
  File "/var/www/ElderMedManagement/zenboPack/pyzenbo/pyzenbo/__init__.py", line 12, in connect
    return PyZenbo(destination, on_state_change_callback, on_result_callback)
  File "/var/www/ElderMedManagement/zenboPack/pyzenbo/pyzenbo/py_zenbo_sdk.py", line 90, in __init__
    on_result_callback, timeout=2)
  File "/var/www/ElderMedManagement/zenboPack/pyzenbo/pyzenbo/modules/inter_communication.py", line 95, in init
    self.skt = SocketStateMachine(destination, timeout)
  File "/var/www/ElderMedManagement/zenboPack/pyzenbo/pyzenbo/modules/socket_state_machine.py", line 30, in __init__
    self.socketSend = self._connect(SOCKET_TYPE['Send'])
  File "/var/www/ElderMedManagement/zenboPack/pyzenbo/pyzenbo/modules/socket_state_machine.py", line 80, in _connect
    self.destination, self.timeout)
  File "/usr/lib/python3.7/socket.py", line 727, in create_connection
    raise err
  File "/usr/lib/python3.7/socket.py", line 716, in create_connection
    sock.connect(sa)
OSError: [Errno 113] No route to host
Traceback (most recent call last):
  File "/var/www/ElderMedManagement/zenboPack/zenboProximoMedicamento.py", line 126, in <module>
    response = getTreatment(userId)
  File "/var/www/ElderMedManagement/zenboPack/zenboProximoMedicamento.py", line 47, in getTreatment
    calcHorario = calcularHorario(i['atendido'], medicationData[1], i, medicationData[0])
  File "/var/www/ElderMedManagement/zenboPack/zenboProximoMedicamento.py", line 60, in calcularHorario
    ano = int(dateString[6:10])
ValueError: invalid literal for int() with base 10: ''
Traceback (most recent call last):
  File "/home/pi/.local/share/virtualenvs/apiSrc_application--FjrzVKE/lib/python3.7/site-packages/urllib3/connection.py", line 170, in _new_conn
    (self._dns_host, self.port), self.timeout, **extra_kw
  File "/home/pi/.local/share/virtualenvs/apiSrc_application--FjrzVKE/lib/python3.7/site-packages/urllib3/util/connection.py", line 96, in create_connection
    raise err
  File "/home/pi/.local/share/virtualenvs/apiSrc_application--FjrzVKE/lib/python3.7/site-packages/urllib3/util/connection.py", line 86, in create_connection
    sock.connect(sa)
OSError: [Errno 113] No route to host

During handling of the above exception, another exception occurred:

Traceback (most recent call last):
  File "/home/pi/.local/share/virtualenvs/apiSrc_application--FjrzVKE/lib/python3.7/site-packages/urllib3/connectionpool.py", line 706, in urlopen
    chunked=chunked,
  File "/home/pi/.local/share/virtualenvs/apiSrc_application--FjrzVKE/lib/python3.7/site-packages/urllib3/connectionpool.py", line 394, in _make_request
    conn.request(method, url, **httplib_request_kw)
  File "/home/pi/.local/share/virtualenvs/apiSrc_application--FjrzVKE/lib/python3.7/site-packages/urllib3/connection.py", line 234, in request
    super(HTTPConnection, self).request(method, url, body=body, headers=headers)
  File "/usr/lib/python3.7/http/client.py", line 1260, in request
    self._send_request(method, url, body, headers, encode_chunked)
  File "/usr/lib/python3.7/http/client.py", line 1306, in _send_request
    self.endheaders(body, encode_chunked=encode_chunked)
  File "/usr/lib/python3.7/http/client.py", line 1255, in endheaders
    self._send_output(message_body, encode_chunked=encode_chunked)
  File "/usr/lib/python3.7/http/client.py", line 1030, in _send_output
    self.send(msg)
  File "/usr/lib/python3.7/http/client.py", line 970, in send
    self.connect()
  File "/home/pi/.local/share/virtualenvs/apiSrc_application--FjrzVKE/lib/python3.7/site-packages/urllib3/connection.py", line 200, in connect
    conn = self._new_conn()
  File "/home/pi/.local/share/virtualenvs/apiSrc_application--FjrzVKE/lib/python3.7/site-packages/urllib3/connection.py", line 182, in _new_conn
    self, "Failed to establish a new connection: %s" % e
urllib3.exceptions.NewConnectionError: <urllib3.connection.HTTPConnection object at 0x7610f430>: Failed to establish a new connection: [Errno 113] No route to host

During handling of the above exception, another exception occurred:

Traceback (most recent call last):
  File "/home/pi/.local/share/virtualenvs/apiSrc_application--FjrzVKE/lib/python3.7/site-packages/requests/adapters.py", line 449, in send
    timeout=timeout
  File "/home/pi/.local/share/virtualenvs/apiSrc_application--FjrzVKE/lib/python3.7/site-packages/urllib3/connectionpool.py", line 756, in urlopen
    method, url, error=e, _pool=self, _stacktrace=sys.exc_info()[2]
  File "/home/pi/.local/share/virtualenvs/apiSrc_application--FjrzVKE/lib/python3.7/site-packages/urllib3/util/retry.py", line 574, in increment
    raise MaxRetryError(_pool, url, error or ResponseError(cause))
urllib3.exceptions.MaxRetryError: HTTPConnectionPool(host='192.168.7.22', port=1515): Max retries exceeded with url: /api/data/appointment/idDate?id=2&date=2022-09-07 (Caused by NewConnectionError('<urllib3.connection.HTTPConnection object at 0x7610f430>: Failed to establish a new connection: [Errno 113] No route to host'))

During handling of the above exception, another exception occurred:

Traceback (most recent call last):
  File "/var/www/ElderMedManagement/zenboPack/zenboCompromissosDoDia.py", line 110, in <module>
    response = getAppointments(userId)
  File "/var/www/ElderMedManagement/zenboPack/zenboCompromissosDoDia.py", line 39, in getAppointments
    response = requests.get(api_endpoint + request_endpoint)
  File "/home/pi/.local/share/virtualenvs/apiSrc_application--FjrzVKE/lib/python3.7/site-packages/requests/api.py", line 75, in get
    return request('get', url, params=params, **kwargs)
  File "/home/pi/.local/share/virtualenvs/apiSrc_application--FjrzVKE/lib/python3.7/site-packages/requests/api.py", line 61, in request
    return session.request(method=method, url=url, **kwargs)
  File "/home/pi/.local/share/virtualenvs/apiSrc_application--FjrzVKE/lib/python3.7/site-packages/requests/sessions.py", line 542, in request
    resp = self.send(prep, **send_kwargs)
  File "/home/pi/.local/share/virtualenvs/apiSrc_application--FjrzVKE/lib/python3.7/site-packages/requests/sessions.py", line 655, in send
    r = adapter.send(request, **kwargs)
  File "/home/pi/.local/share/virtualenvs/apiSrc_application--FjrzVKE/lib/python3.7/site-packages/requests/adapters.py", line 516, in send
    raise ConnectionError(e, request=request)
requests.exceptions.ConnectionError: HTTPConnectionPool(host='192.168.7.22', port=1515): Max retries exceeded with url: /api/data/appointment/idDate?id=2&date=2022-09-07 (Caused by NewConnectionError('<urllib3.connection.HTTPConnection object at 0x7610f430>: Failed to establish a new connection: [Errno 113] No route to host'))
Receiver socket connect failed
Sender socket connect failed
Traceback (most recent call last):
  File "/home/pi/.local/share/virtualenvs/apiSrc_application--FjrzVKE/lib/python3.7/site-packages/urllib3/connection.py", line 170, in _new_conn
    (self._dns_host, self.port), self.timeout, **extra_kw
  File "/home/pi/.local/share/virtualenvs/apiSrc_application--FjrzVKE/lib/python3.7/site-packages/urllib3/util/connection.py", line 96, in create_connection
    raise err
  File "/home/pi/.local/share/virtualenvs/apiSrc_application--FjrzVKE/lib/python3.7/site-packages/urllib3/util/connection.py", line 86, in create_connection
    sock.connect(sa)
OSError: [Errno 113] No route to host

During handling of the above exception, another exception occurred:

Traceback (most recent call last):
  File "/home/pi/.local/share/virtualenvs/apiSrc_application--FjrzVKE/lib/python3.7/site-packages/urllib3/connectionpool.py", line 706, in urlopen
    chunked=chunked,
  File "/home/pi/.local/share/virtualenvs/apiSrc_application--FjrzVKE/lib/python3.7/site-packages/urllib3/connectionpool.py", line 394, in _make_request
    conn.request(method, url, **httplib_request_kw)
  File "/home/pi/.local/share/virtualenvs/apiSrc_application--FjrzVKE/lib/python3.7/site-packages/urllib3/connection.py", line 234, in request
    super(HTTPConnection, self).request(method, url, body=body, headers=headers)
  File "/usr/lib/python3.7/http/client.py", line 1260, in request
    self._send_request(method, url, body, headers, encode_chunked)
  File "/usr/lib/python3.7/http/client.py", line 1306, in _send_request
    self.endheaders(body, encode_chunked=encode_chunked)
  File "/usr/lib/python3.7/http/client.py", line 1255, in endheaders
    self._send_output(message_body, encode_chunked=encode_chunked)
  File "/usr/lib/python3.7/http/client.py", line 1030, in _send_output
    self.send(msg)
  File "/usr/lib/python3.7/http/client.py", line 970, in send
    self.connect()
  File "/home/pi/.local/share/virtualenvs/apiSrc_application--FjrzVKE/lib/python3.7/site-packages/urllib3/connection.py", line 200, in connect
    conn = self._new_conn()
  File "/home/pi/.local/share/virtualenvs/apiSrc_application--FjrzVKE/lib/python3.7/site-packages/urllib3/connection.py", line 182, in _new_conn
    self, "Failed to establish a new connection: %s" % e
urllib3.exceptions.NewConnectionError: <urllib3.connection.HTTPConnection object at 0x760a5250>: Failed to establish a new connection: [Errno 113] No route to host

During handling of the above exception, another exception occurred:

Traceback (most recent call last):
  File "/home/pi/.local/share/virtualenvs/apiSrc_application--FjrzVKE/lib/python3.7/site-packages/requests/adapters.py", line 449, in send
    timeout=timeout
  File "/home/pi/.local/share/virtualenvs/apiSrc_application--FjrzVKE/lib/python3.7/site-packages/urllib3/connectionpool.py", line 756, in urlopen
    method, url, error=e, _pool=self, _stacktrace=sys.exc_info()[2]
  File "/home/pi/.local/share/virtualenvs/apiSrc_application--FjrzVKE/lib/python3.7/site-packages/urllib3/util/retry.py", line 574, in increment
    raise MaxRetryError(_pool, url, error or ResponseError(cause))
urllib3.exceptions.MaxRetryError: HTTPConnectionPool(host='192.168.7.22', port=1515): Max retries exceeded with url: /api/data/treatment/id?id=2 (Caused by NewConnectionError('<urllib3.connection.HTTPConnection object at 0x760a5250>: Failed to establish a new connection: [Errno 113] No route to host'))

During handling of the above exception, another exception occurred:

Traceback (most recent call last):
  File "/var/www/ElderMedManagement/zenboPack/zenboInformacaoTratamento.py", line 89, in <module>
    response = getTreatment(userId)
  File "/var/www/ElderMedManagement/zenboPack/zenboInformacaoTratamento.py", line 32, in getTreatment
    response = requests.get(api_endpoint + request_endpoint)
  File "/home/pi/.local/share/virtualenvs/apiSrc_application--FjrzVKE/lib/python3.7/site-packages/requests/api.py", line 75, in get
    return request('get', url, params=params, **kwargs)
  File "/home/pi/.local/share/virtualenvs/apiSrc_application--FjrzVKE/lib/python3.7/site-packages/requests/api.py", line 61, in request
    return session.request(method=method, url=url, **kwargs)
  File "/home/pi/.local/share/virtualenvs/apiSrc_application--FjrzVKE/lib/python3.7/site-packages/requests/sessions.py", line 542, in request
    resp = self.send(prep, **send_kwargs)
  File "/home/pi/.local/share/virtualenvs/apiSrc_application--FjrzVKE/lib/python3.7/site-packages/requests/sessions.py", line 655, in send
    r = adapter.send(request, **kwargs)
  File "/home/pi/.local/share/virtualenvs/apiSrc_application--FjrzVKE/lib/python3.7/site-packages/requests/adapters.py", line 516, in send
    raise ConnectionError(e, request=request)
requests.exceptions.ConnectionError: HTTPConnectionPool(host='192.168.7.22', port=1515): Max retries exceeded with url: /api/data/treatment/id?id=2 (Caused by NewConnectionError('<urllib3.connection.HTTPConnection object at 0x760a5250>: Failed to establish a new connection: [Errno 113] No route to host'))
Receiver socket connect failed
Sender socket connect failed
Traceback (most recent call last):
  File "/home/pi/.local/share/virtualenvs/apiSrc_application--FjrzVKE/lib/python3.7/site-packages/urllib3/connection.py", line 170, in _new_conn
    (self._dns_host, self.port), self.timeout, **extra_kw
  File "/home/pi/.local/share/virtualenvs/apiSrc_application--FjrzVKE/lib/python3.7/site-packages/urllib3/util/connection.py", line 96, in create_connection
    raise err
  File "/home/pi/.local/share/virtualenvs/apiSrc_application--FjrzVKE/lib/python3.7/site-packages/urllib3/util/connection.py", line 86, in create_connection
    sock.connect(sa)
OSError: [Errno 113] No route to host

During handling of the above exception, another exception occurred:

Traceback (most recent call last):
  File "/home/pi/.local/share/virtualenvs/apiSrc_application--FjrzVKE/lib/python3.7/site-packages/urllib3/connectionpool.py", line 706, in urlopen
    chunked=chunked,
  File "/home/pi/.local/share/virtualenvs/apiSrc_application--FjrzVKE/lib/python3.7/site-packages/urllib3/connectionpool.py", line 394, in _make_request
    conn.request(method, url, **httplib_request_kw)
  File "/home/pi/.local/share/virtualenvs/apiSrc_application--FjrzVKE/lib/python3.7/site-packages/urllib3/connection.py", line 234, in request
    super(HTTPConnection, self).request(method, url, body=body, headers=headers)
  File "/usr/lib/python3.7/http/client.py", line 1260, in request
    self._send_request(method, url, body, headers, encode_chunked)
  File "/usr/lib/python3.7/http/client.py", line 1306, in _send_request
    self.endheaders(body, encode_chunked=encode_chunked)
  File "/usr/lib/python3.7/http/client.py", line 1255, in endheaders
    self._send_output(message_body, encode_chunked=encode_chunked)
  File "/usr/lib/python3.7/http/client.py", line 1030, in _send_output
    self.send(msg)
  File "/usr/lib/python3.7/http/client.py", line 970, in send
    self.connect()
  File "/home/pi/.local/share/virtualenvs/apiSrc_application--FjrzVKE/lib/python3.7/site-packages/urllib3/connection.py", line 200, in connect
    conn = self._new_conn()
  File "/home/pi/.local/share/virtualenvs/apiSrc_application--FjrzVKE/lib/python3.7/site-packages/urllib3/connection.py", line 182, in _new_conn
    self, "Failed to establish a new connection: %s" % e
urllib3.exceptions.NewConnectionError: <urllib3.connection.HTTPConnection object at 0x760d2230>: Failed to establish a new connection: [Errno 113] No route to host

During handling of the above exception, another exception occurred:

Traceback (most recent call last):
  File "/home/pi/.local/share/virtualenvs/apiSrc_application--FjrzVKE/lib/python3.7/site-packages/requests/adapters.py", line 449, in send
    timeout=timeout
  File "/home/pi/.local/share/virtualenvs/apiSrc_application--FjrzVKE/lib/python3.7/site-packages/urllib3/connectionpool.py", line 756, in urlopen
    method, url, error=e, _pool=self, _stacktrace=sys.exc_info()[2]
  File "/home/pi/.local/share/virtualenvs/apiSrc_application--FjrzVKE/lib/python3.7/site-packages/urllib3/util/retry.py", line 574, in increment
    raise MaxRetryError(_pool, url, error or ResponseError(cause))
urllib3.exceptions.MaxRetryError: HTTPConnectionPool(host='192.168.7.22', port=1515): Max retries exceeded with url: /api/data/treatment/id?id=3 (Caused by NewConnectionError('<urllib3.connection.HTTPConnection object at 0x760d2230>: Failed to establish a new connection: [Errno 113] No route to host'))

During handling of the above exception, another exception occurred:

Traceback (most recent call last):
  File "/var/www/ElderMedManagement/zenboPack/zenboInformacaoTratamento.py", line 89, in <module>
    response = getTreatment(userId)
  File "/var/www/ElderMedManagement/zenboPack/zenboInformacaoTratamento.py", line 32, in getTreatment
    response = requests.get(api_endpoint + request_endpoint)
  File "/home/pi/.local/share/virtualenvs/apiSrc_application--FjrzVKE/lib/python3.7/site-packages/requests/api.py", line 75, in get
    return request('get', url, params=params, **kwargs)
  File "/home/pi/.local/share/virtualenvs/apiSrc_application--FjrzVKE/lib/python3.7/site-packages/requests/api.py", line 61, in request
    return session.request(method=method, url=url, **kwargs)
  File "/home/pi/.local/share/virtualenvs/apiSrc_application--FjrzVKE/lib/python3.7/site-packages/requests/sessions.py", line 542, in request
    resp = self.send(prep, **send_kwargs)
  File "/home/pi/.local/share/virtualenvs/apiSrc_application--FjrzVKE/lib/python3.7/site-packages/requests/sessions.py", line 655, in send
    r = adapter.send(request, **kwargs)
  File "/home/pi/.local/share/virtualenvs/apiSrc_application--FjrzVKE/lib/python3.7/site-packages/requests/adapters.py", line 516, in send
    raise ConnectionError(e, request=request)
requests.exceptions.ConnectionError: HTTPConnectionPool(host='192.168.7.22', port=1515): Max retries exceeded with url: /api/data/treatment/id?id=3 (Caused by NewConnectionError('<urllib3.connection.HTTPConnection object at 0x760d2230>: Failed to establish a new connection: [Errno 113] No route to host'))
